Workbook

Sheet 3 candidates_LS-2014
H1: 0 | I1: 1 | J1: 2 | K1: 3 | L1: 4 | M1: 5 | N1: 6 | O1: 7 | P1: 8 | Q1: 9 | R1: 10 | S1: 11 | T1: 12 | U1: 13 | V1: 14 | W1: 15 | X1: 16 | Y1: 17 | Z1: 18 | AA1: 19 | AB1: 20 | AC1: 21 | AD1: 22 | AE1: 23 | AF1: 24 | AG1: 25 | AH1: 26 | AI1: 27 | AJ1: 28 | AK1: 29 | AL1: 30 | AM1: 31 | AN1: 32 | AO1: 33 | AP1: 34 | AQ1: 35 | AR1: 36 | AS1: 37 | AT1: 38 | AU1: 39 | AV1: 40 | AW1: 41 | AX1: 42
A2: state | B2: statecode | C2: constituency_no | D2: No_Candidates | E2: constituency | F2: year | G2: Classification | H2: first | I2: second | J2: third | K2: fourth | L2: fifth | M2: sixth | N2: seventh | O2: eighth | P2: ninth | Q2: tenth | R2: eleventh | S2: twelveth | T2: thirteenth | U2: fourteenth | V2: fifteenth | W2: sixteenth | X2: seventeenth | Y2: eighteenth | Z2: nineteenth | AA2: twentieth | AB2: twentyfirst | AC2: twentysecond | AD2: twentythird | AE2: twentyfourth | AF2: twentyfifth | AG2: twentysixth | AH2: twentyseventh | AI2: twentyeighth | AJ2: twentyninth | AK2: thirtieth | AL2: thirtyfirst | AM2: thirtysecond | AN2: thirtythird | AO2: thirtyfourth | AP2: thirtyfifth | AQ2: thirtysixth | AR2: thirtyseventh | AS2: thirtyeightth | AT2: thirtyninth | AU2: fortieth | AV2: fortyfirst | AW2: fortysecond | AX2: fortythird | AY2: total | AZ2: Winner_vote_share | BA2: Flag_1 | BB2: A_share | BC2: B_share | BD2: C_share | BE2: OWNCM_PCP | BF2: WPCW | BG2: PBP
A3: Andhra Pradesh | C3: 1 | D3: 9 | E3: Adilabad | F3: 2014 | H3: 430847 | I3: 259557 | J3: 184198 | K3: 94420 | L3: 41032 | M3: 17084 | N3: 8859 | O3: 5055 | P3: 4787 | Q3: 0 | R3: 0 | S3: 0 | T3: 0 | U3: 0 | V3: 0 | W3: 0 | X3: 0 | Y3: 0 | Z3: 0 | AA3: 0 | AB3: 0 | AC3: 0 | AD3: 0 | AE3: 0 | AF3: 0 | AG3: 0 | AH3: 0 | AI3: 0 | AJ3: 0 | AK3: 0 | AL3: 0 | AM3: 0 | AN3: 0 | AO3: 0 | AP3: 0 | AQ3: 0 | AR3: 0 | AS3: 0 | AT3: 0 | AU3: 0 | AV3: 0 | AW3: 0 | AX3: 0 | AY3: 1045839
A4: Andhra Pradesh | C4: 2 | D4: 18 | E4: Peddapalle | F4: 2014 | H4: 565496 | I4: 274338 | J4: 63334 | K4: 45977 | L4: 9449 | M4: 9290 | N4: 9199 | O4: 8609 | P4: 7258 | Q4: 5361 | R4: 3866 | S4: 3699 | T4: 3266 | U4: 3020 | V4: 2742 | W4: 2674 | X4: 2361 | Y4: 2245 | Z4: 0 | AA4: 0 | AB4: 0 | AC4: 0 | AD4: 0 | AE4: 0 | AF4: 0 | AG4: 0 | AH4: 0 | AI4: 0 | AJ4: 0 | AK4: 0 | AL4: 0 | AM4: 0 | AN4: 0 | AO4: 0 | AP4: 0 | AQ4: 0 | AR4: 0 | AS4: 0 | AT4: 0 | AU4: 0 | AV4: 0 | AW4: 0 | AX4: 0 | AY4: 1022184
A5: Andhra Pradesh | C5: 3 | D5: 18 | E5: Karimnagar | F5: 2014 | H5: 505358 | I5: 300706 | J5: 214828 | K5: 39308 | L5: 11328 | M5: 8034 | N5: 6713 | O5: 5734 | P5: 4769 | Q5: 4728 | R5: 3943 | S5: 3851 | T5: 3772 | U5: 3075 | V5: 2757 | W5: 2445 | X5: 2062 | Y5: 1773 | Z5: 0 | AA5: 0 | AB5: 0 | AC5: 0 | AD5: 0 | AE5: 0 | AF5: 0 | AG5: 0 | AH5: 0 | AI5: 0 | AJ5: 0 | AK5: 0 | AL5: 0 | AM5: 0 | AN5: 0 | AO5: 0 | AP5: 0 | AQ5: 0 | AR5: 0 | AS5: 0 | AT5: 0 | AU5: 0 | AV5: 0 | AW5: 0 | AX5: 0 | AY5: 1125184
A6: Andhra Pradesh | C6: 4 | D6: 17 | E6: Nizamabad | F6: 2014 | H6: 439307 | I6: 272123 | J6: 225333 | K6: 43814 | L6: 8129 | M6: 7421 | N6: 7266 | O6: 4791 | P6: 3990 | Q6: 3651 | R6: 3529 | S6: 3091 | T6: 2817 | U6: 2621 | V6: 2462 | W6: 1978 | X6: 1601 | Y6: 0 | Z6: 0 | AA6: 0 | AB6: 0 | AC6: 0 | AD6: 0 | AE6: 0 | AF6: 0 | AG6: 0 | AH6: 0 | AI6: 0 | AJ6: 0 | AK6: 0 | AL6: 0 | AM6: 0 | AN6: 0 | AO6: 0 | AP6: 0 | AQ6: 0 | AR6: 0 | AS6: 0 | AT6: 0 | AU6: 0 | AV6: 0 | AW6: 0 | AX6: 0 | AY6: 1033924
A7: Andhra Pradesh | C7: 5 | D7: 11 | E7: Zahirabad | F7: 2014 | H7: 508661 | I7: 364030 | J7: 157497 | K7: 18027 | L7: 12383 | M7: 11190 | N7: 8180 | O7: 4804 | P7: 4426 | Q7: 3285 | R7: 2323 | S7: 0 | T7: 0 | U7: 0 | V7: 0 | W7: 0 | X7: 0 | Y7: 0 | Z7: 0 | AA7: 0 | AB7: 0 | AC7: 0 | AD7: 0 | AE7: 0 | AF7: 0 | AG7: 0 | AH7: 0 | AI7: 0 | AJ7: 0 | AK7: 0 | AL7: 0 | AM7: 0 | AN7: 0 | AO7: 0 | AP7: 0 | AQ7: 0 | AR7: 0 | AS7: 0 | AT7: 0 | AU7: 0 | AV7: 0 | AW7: 0 | AX7: 0 | AY7: 1094806
A8: Andhra Pradesh | C8: 6 | D8: 14 | E8: Medak | F8: 2014 | H8: 657492 | I8: 260463 | J8: 181804 | K8: 33507 | L8: 11752 | M8: 10696 | N8: 7599 | O8: 6643 | P8: 5010 | Q8: 4441 | R8: 3297 | S8: 3281 | T8: 2973 | U8: 2053 | V8: 0 | W8: 0 | X8: 0 | Y8: 0 | Z8: 0 | AA8: 0 | AB8: 0 | AC8: 0 | AD8: 0 | AE8: 0 | AF8: 0 | AG8: 0 | AH8: 0 | AI8: 0 | AJ8: 0 | AK8: 0 | AL8: 0 | AM8: 0 | AN8: 0 | AO8: 0 | AP8: 0 | AQ8: 0 | AR8: 0 | AS8: 0 | AT8: 0 | AU8: 0 | AV8: 0 | AW8: 0 | AX8: 0 | AY8: 1191011
A9: Andhra Pradesh | C9: 7 | D9: 31 | E9: Malkajgiri | F9: 2014 | H9: 523356 | I9: 495190 | J9: 233530 | K9: 158248 | L9: 115221 | M9: 18544 | N9: 13239 | O9: 8692 | P9: 8301 | Q9: 7953 | R9: 6133 | S9: 5717 | T9: 4095 | U9: 2677 | V9: 2261 | W9: 2049 | X9: 1693 | Y9: 1547 | Z9: 1416 | AA9: 1390 | AB9: 1325 | AC9: 1301 | AD9: 1032 | AE9: 1026 | AF9: 899 | AG9: 802 | AH9: 775 | AI9: 596 | AJ9: 529 | AK9: 496 | AL9: 411 | AM9: 0 | AN9: 0 | AO9: 0 | AP9: 0 | AQ9: 0 | AR9: 0 | AS9: 0 | AT9: 0 | AU9: 0 | AV9: 0 | AW9: 0 | AX9: 0 | AY9: 1620444
A10: Andhra Pradesh | C10: 8 | D10: 31 | E10: Secundrabad | F10: 2014 | H10: 438271 | I10: 183536 | J10: 145120 | K10: 143847 | L10: 45187 | M10: 11184 | N10: 6572 | O10: 3691 | P10: 2863 | Q10: 2603 | R10: 2481 | S10: 2311 | T10: 2058 | U10: 1813 | V10: 1496 | W10: 1144 | X10: 959 | Y10: 928 | Z10: 886 | AA10: 873 | AB10: 809 | AC10: 786 | AD10: 779 | AE10: 638 | AF10: 554 | AG10: 547 | AH10: 474 | AI10: 376 | AJ10: 370 | AK10: 322 | AL10: 291 | AM10: 0 | AN10: 0 | AO10: 0 | AP10: 0 | AQ10: 0 | AR10: 0 | AS10: 0 | AT10: 0 | AU10: 0 | AV10: 0 | AW10: 0 | AX10: 0 | AY10: 1003769
A11: Andhra Pradesh | C11: 9 | D11: 17 | E11: Hyderbad | F11: 2014 | H11: 513868 | I11: 311414 | J11: 49310 | K11: 37195 | L11: 21796 | M11: 10743 | N11: 6118 | O11: 5992 | P11: 5013 | Q11: 3100 | R11: 2102 | S11: 1593 | T11: 740 | U11: 728 | V11: 626 | W11: 598 | X11: 485 | Y11: 0 | Z11: 0 | AA11: 0 | AB11: 0 | AC11: 0 | AD11: 0 | AE11: 0 | AF11: 0 | AG11: 0 | AH11: 0 | AI11: 0 | AJ11: 0 | AK11: 0 | AL11: 0 | AM11: 0 | AN11: 0 | AO11: 0 | AP11: 0 | AQ11: 0 | AR11: 0 | AS11: 0 | AT11: 0 | AU11: 0 | AV11: 0 | AW11: 0 | AX11: 0 | AY11: 971421
A12: Andhra Pradesh | C12: 10 | D12: 16 | E12: Chelvella | F12: 2014 | H12: 435077 | I12: 362054 | J12: 353203 | K12: 56835 | L12: 40135 | M12: 24660 | N12: 10018 | O12: 7732 | P12: 7462 | Q12: 5789 | R12: 2904 | S12: 2545 | T12: 2214 | U12: 2058 | V12: 1765 | W12: 1411 | X12: 0 | Y12: 0 | Z12: 0 | AA12: 0 | AB12: 0 | AC12: 0 | AD12: 0 | AE12: 0 | AF12: 0 | AG12: 0 | AH12: 0 | AI12: 0 | AJ12: 0 | AK12: 0 | AL12: 0 | AM12: 0 | AN12: 0 | AO12: 0 | AP12: 0 | AQ12: 0 | AR12: 0 | AS12: 0 | AT12: 0 | AU12: 0 | AV12: 0 | AW12: 0 | AX12: 0 | AY12: 1315862
A13: Andhra Pradesh | C13: 11 | D13: 10 | E13: Mahbubnagar | F13: 2014 | H13: 334228 | I13: 331638 | J13: 272791 | K13: 30388 | L13: 15779 | M13: 9105 | N13: 9037 | O13: 4549 | P13: 4033 | Q13: 3252 | R13: 0 | S13: 0 | T13: 0 | U13: 0 | V13: 0 | W13: 0 | X13: 0 | Y13: 0 | Z13: 0 | AA13: 0 | AB13: 0 | AC13: 0 | AD13: 0 | AE13: 0 | AF13: 0 | AG13: 0 | AH13: 0 | AI13: 0 | AJ13: 0 | AK13: 0 | AL13: 0 | AM13: 0 | AN13: 0 | AO13: 0 | AP13: 0 | AQ13: 0 | AR13: 0 | AS13: 0 | AT13: 0 | AU13: 0 | AV13: 0 | AW13: 0 | AX13: 0 | AY13: 1014800
A14: Andhra Pradesh | C14: 12 | D14: 7 | E14: Nagarkurnool | F14: 2014 | H14: 420075 | I14: 403399 | J14: 183352 | K14: 54680 | L14: 22985 | M14: 12388 | N14: 12089 | O14: 0 | P14: 0 | Q14: 0 | R14: 0 | S14: 0 | T14: 0 | U14: 0 | V14: 0 | W14: 0 | X14: 0 | Y14: 0 | Z14: 0 | AA14: 0 | AB14: 0 | AC14: 0 | AD14: 0 | AE14: 0 | AF14: 0 | AG14: 0 | AH14: 0 | AI14: 0 | AJ14: 0 | AK14: 0 | AL14: 0 | AM14: 0 | AN14: 0 | AO14: 0 | AP14: 0 | AQ14: 0 | AR14: 0 | AS14: 0 | AT14: 0 | AU14: 0 | AV14: 0 | AW14: 0 | AX14: 0 | AY14: 1108968
... A276: Meghalaya | C276: 274 | D276: 9 | E276: Shillong | F276: 2014 | H276: 209340 | I276: 168961 | J276: 106817 | K276: 95979 | L276: 10960 | M276: 8815 | N276: 7418 | O276: 6605 | P276: 5092 | Q276: 0 | R276: 0 | S276: 0 | T276: 0 | U276: 0 | V276: 0 | W276: 0 | X276: 0 | Y276: 0 | Z276: 0 | AA276: 0 | AB276: 0 | AC276: 0 | AD276: 0 | AE276: 0 | AF276: 0 | AG276: 0 | AH276: 0 | AI276: 0 | AJ276: 0 | AK276: 0 | AL276: 0 | AM276: 0 | AN276: 0 | AO276: 0 | AP276: 0 | AQ276: 0 | AR276: 0 | AS276: 0 | AT276: 0 | AU276: 0 | AV276: 0 | AW276: 0 | AX276: 0 | AY276: 619987
A277: Meghalaya | C277: 275 | D277: 3 | E277: Tura | F277: 2014 | H277: 239301 | I277: 199585 | J277: 19185 | K277: 0 | L277: 0 | M277: 0 | N277: 0 | O277: 0 | P277: 0 | Q277: 0 | R277: 0 | S277: 0 | T277: 0 | U277: 0 | V277: 0 | W277: 0 | X277: 0 | Y277: 0 | Z277: 0 | AA277: 0 | AB277: 0 | AC277: 0 | AD277: 0 | AE277: 0 | AF277: 0 | AG277: 0 | AH277: 0 | AI277: 0 | AJ277: 0 | AK277: 0 | AL277: 0 | AM277: 0 | AN277: 0 | AO277: 0 | AP277: 0 | AQ277: 0 | AR277: 0 | AS277: 0 | AT277: 0 | AU277: 0 | AV277: 0 | AW277: 0 | AX277: 0 | AY277: 458071 | AZ277: =MAX(H277:J277)/AY277 -> 0.52241028 | BA277: =IF(AZ277<50%,1,0) -> 0 | BB277: =H277/$AY277 -> 0.52241028 | BC277: =I277/$AY277 -> 0.43570756 | BD277: =J277/$AY277 -> 0.041882154
A278: Mizoram | C278: 276 | D278: 4 | E278: Mizoram | F278: 2014 | H278: 210485 | I278: 204331 | J278: 11890 | K278: 6495 | L278: 0 | M278: 0 | N278: 0 | O278: 0 | P278: 0 | Q278: 0 | R278: 0 | S278: 0 | T278: 0 | U278: 0 | V278: 0 | W278: 0 | X278: 0 | Y278: 0 | Z278: 0 | AA278: 0 | AB278: 0 | AC278: 0 | AD278: 0 | AE278: 0 | AF278: 0 | AG278: 0 | AH278: 0 | AI278: 0 | AJ278: 0 | AK278: 0 | AL278: 0 | AM278: 0 | AN278: 0 | AO278: 0 | AP278: 0 | AQ278: 0 | AR278: 0 | AS278: 0 | AT278: 0 | AU278: 0 | AV278: 0 | AW278: 0 | AX278: 0 | AY278: 433201
A279: Nagaland | C279: 277 | D279: 4 | E279: Nagaland | F279: 2014 | H279: 713372 | I279: 313147 | J279: 9695 | K279: 2696 | L279: 0 | M279: 0 | N279: 0 | O279: 0 | P279: 0 | Q279: 0 | R279: 0 | S279: 0 | T279: 0 | U279: 0 | V279: 0 | W279: 0 | X279: 0 | Y279: 0 | Z279: 0 | AA279: 0 | AB279: 0 | AC279: 0 | AD279: 0 | AE279: 0 | AF279: 0 | AG279: 0 | AH279: 0 | AI279: 0 | AJ279: 0 | AK279: 0 | AL279: 0 | AM279: 0 | AN279: 0 | AO279: 0 | AP279: 0 | AQ279: 0 | AR279: 0 | AS279: 0 | AT279: 0 | AU279: 0 | AV279: 0 | AW279: 0 | AX279: 0 | AY279: 1038910
A280: Orissa | C280: 278 | D280: 9 | E280: Bargarh | F280: 2014 | H280: 383230 | I280: 372052 | J280: 274610 | K280: 26216 | L280: 21100 | M280: 15672 | N280: 14500 | O280: 8009 | P280: 7912 | Q280: 0 | R280: 0 | S280: 0 | T280: 0 | U280: 0 | V280: 0 | W280: 0 | X280: 0 | Y280: 0 | Z280: 0 | AA280: 0 | AB280: 0 | AC280: 0 | AD280: 0 | AE280: 0 | AF280: 0 | AG280: 0 | AH280: 0 | AI280: 0 | AJ280: 0 | AK280: 0 | AL280: 0 | AM280: 0 | AN280: 0 | AO280: 0 | AP280: 0 | AQ280: 0 | AR280: 0 | AS280: 0 | AT280: 0 | AU280: 0 | AV280: 0 | AW280: 0 | AX280: 0 | AY280: 1123301
A281: Orissa | C281: 279 | D281: 13 | E281: Sundargarh | F281: 2014 | H281: 340508 | I281: 321679 | J281: 269335 | K281: 15835 | L281: 9472 | M281: 9460 | N281: 9001 | O281: 8448 | P281: 7429 | Q281: 7282 | R281: 4408 | S281: 3951 | T281: 3903 | U281: 0 | V281: 0 | W281: 0 | X281: 0 | Y281: 0 | Z281: 0 | AA281: 0 | AB281: 0 | AC281: 0 | AD281: 0 | AE281: 0 | AF281: 0 | AG281: 0 | AH281: 0 | AI281: 0 | AJ281: 0 | AK281: 0 | AL281: 0 | AM281: 0 | AN281: 0 | AO281: 0 | AP281: 0 | AQ281: 0 | AR281: 0 | AS281: 0 | AT281: 0 | AU281: 0 | AV281: 0 | AW281: 0 | AX281: 0 | AY281: 1010711
A282: Orissa | C282: 280 | D282: 12 | E282: Sambalpur | F282: 2014 | H282: 358618 | I282: 328042 | J282: 242131 | K282: 13314 | L282: 12211 | M282: 7029 | N282: 4763 | O282: 4502 | P282: 4018 | Q282: 4012 | R282: 3110 | S282: 2559 | T282: 0 | U282: 0 | V282: 0 | W282: 0 | X282: 0 | Y282: 0 | Z282: 0 | AA282: 0 | AB282: 0 | AC282: 0 | AD282: 0 | AE282: 0 | AF282: 0 | AG282: 0 | AH282: 0 | AI282: 0 | AJ282: 0 | AK282: 0 | AL282: 0 | AM282: 0 | AN282: 0 | AO282: 0 | AP282: 0 | AQ282: 0 | AR282: 0 | AS282: 0 | AT282: 0 | AU282: 0 | AV282: 0 | AW282: 0 | AX282: 0 | AY282: 984309
A283: Orissa | C283: 281 | D283: 9 | E283: Keonjhar | F283: 2014 | H283: 434471 | I283: 277154 | J283: 190531 | K283: 101999 | L283: 26065 | M283: 16420 | N283: 16299 | O283: 12236 | P283: 8694 | Q283: 0 | R283: 0 | S283: 0 | T283: 0 | U283: 0 | V283: 0 | W283: 0 | X283: 0 | Y283: 0 | Z283: 0 | AA283: 0 | AB283: 0 | AC283: 0 | AD283: 0 | AE283: 0 | AF283: 0 | AG283: 0 | AH283: 0 | AI283: 0 | AJ283: 0 | AK283: 0 | AL283: 0 | AM283: 0 | AN283: 0 | AO283: 0 | AP283: 0 | AQ283: 0 | AR283: 0 | AS283: 0 | AT283: 0 | AU283: 0 | AV283: 0 | AW283: 0 | AX283: 0 | AY283: 1083869
A284: Orissa | C284: 282 | D284: 10 | E284: Mayurbhanj | F284: 2014 | H284: 393779 | I284: 270913 | J284: 172984 | K284: 142165 | L284: 23517 | M284: 14632 | N284: 12041 | O284: 8183 | P284: 8133 | Q284: 7052 | R284: 0 | S284: 0 | T284: 0 | U284: 0 | V284: 0 | W284: 0 | X284: 0 | Y284: 0 | Z284: 0 | AA284: 0 | AB284: 0 | AC284: 0 | AD284: 0 | AE284: 0 | AF284: 0 | AG284: 0 | AH284: 0 | AI284: 0 | AJ284: 0 | AK284: 0 | AL284: 0 | AM284: 0 | AN284: 0 | AO284: 0 | AP284: 0 | AQ284: 0 | AR284: 0 | AS284: 0 | AT284: 0 | AU284: 0 | AV284: 0 | AW284: 0 | AX284: 0 | AY284: 1053399
A285: Orissa | C285: 283 | D285: 11 | E285: Balasore | F285: 2014 | H285: 433768 | I285: 291943 | J285: 277517 | K285: 14538 | L285: 9856 | M285: 7716 | N285: 4529 | O285: 3240 | P285: 2664 | Q285: 1856 | R285: 1823 | S285: 0 | T285: 0 | U285: 0 | V285: 0 | W285: 0 | X285: 0 | Y285: 0 | Z285: 0 | AA285: 0 | AB285: 0 | AC285: 0 | AD285: 0 | AE285: 0 | AF285: 0 | AG285: 0 | AH285: 0 | AI285: 0 | AJ285: 0 | AK285: 0 | AL285: 0 | AM285: 0 | AN285: 0 | AO285: 0 | AP285: 0 | AQ285: 0 | AR285: 0 | AS285: 0 | AT285: 0 | AU285: 0 | AV285: 0 | AW285: 0 | AX285: 0 | AY285: 1049450
A286: Orissa | C286: 284 | D286: 9 | E286: Bhadrak | F286: 2014 | H286: 502338 | I286: 322979 | J286: 216617 | K286: 11930 | L286: 7607 | M286: 6750 | N286: 5961 | O286: 4518 | P286: 2639 | Q286: 0 | R286: 0 | S286: 0 | T286: 0 | U286: 0 | V286: 0 | W286: 0 | X286: 0 | Y286: 0 | Z286: 0 | AA286: 0 | AB286: 0 | AC286: 0 | AD286: 0 | AE286: 0 | AF286: 0 | AG286: 0 | AH286: 0 | AI286: 0 | AJ286: 0 | AK286: 0 | AL286: 0 | AM286: 0 | AN286: 0 | AO286: 0 | AP286: 0 | AQ286: 0 | AR286: 0 | AS286: 0 | AT286: 0 | AU286: 0 | AV286: 0 | AW286: 0 | AX286: 0 | AY286: 1081339
A287: Orissa | C287: 285 | D287: 10 | E287: Jajpur | F287: 2014 | H287: 541349 | I287: 221078 | J287: 150789 | K287: 29142 | L287: 8655 | M287: 8269 | N287: 8065 | O287: 6926 | P287: 3409 | Q287: 2753 | R287: 0 | S287: 0 | T287: 0 | U287: 0 | V287: 0 | W287: 0 | X287: 0 | Y287: 0 | Z287: 0 | AA287: 0 | AB287: 0 | AC287: 0 | AD287: 0 | AE287: 0 | AF287: 0 | AG287: 0 | AH287: 0 | AI287: 0 | AJ287: 0 | AK287: 0 | AL287: 0 | AM287: 0 | AN287: 0 | AO287: 0 | AP287: 0 | AQ287: 0 | AR287: 0 | AS287: 0 | AT287: 0 | AU287: 0 | AV287: 0 | AW287: 0 | AX287: 0 | AY287: 980435
A288: Orissa | C288: 286 | D288: 13 | E288: Dhenkanal | F288: 2014 | H288: 453277 | I288: 315937 | J288: 213794 | K288: 13205 | L288: 8712 | M288: 7505 | N288: 6574 | O288: 5447 | P288: 5120 | Q288: 4275 | R288: 3918 | S288: 2298 | T288: 2039 | U288: 0 | V288: 0 | W288: 0 | X288: 0 | Y288: 0 | Z288: 0 | AA288: 0 | AB288: 0 | AC288: 0 | AD288: 0 | AE288: 0 | AF288: 0 | AG288: 0 | AH288: 0 | AI288: 0 | AJ288: 0 | AK288: 0 | AL288: 0 | AM288: 0 | AN288: 0 | AO288: 0 | AP288: 0 | AQ288: 0 | AR288: 0 | AS288: 0 | AT288: 0 | AU288: 0 | AV288: 0 | AW288: 0 | AX288: 0 | AY288: 1042101
A289: Orissa | C289: 287 | D289: 9 | E289: Bolangir | F289: 2014 | H289: 453519 | I289: 349220 | J289: 277616 | K289: 24515 | L289: 21043 | M289: 14626 | N289: 11513 | O289: 9915 | P289: 8438 | Q289: 0 | R289: 0 | S289: 0 | T289: 0 | U289: 0 | V289: 0 | W289: 0 | X289: 0 | Y289: 0 | Z289: 0 | AA289: 0 | AB289: 0 | AC289: 0 | AD289: 0 | AE289: 0 | AF289: 0 | AG289: 0 | AH289: 0 | AI289: 0 | AJ289: 0 | AK289: 0 | AL289: 0 | AM289: 0 | AN289: 0 | AO289: 0 | AP289: 0 | AQ289: 0 | AR289: 0 | AS289: 0 | AT289: 0 | AU289: 0 | AV289: 0 | AW289: 0 | AX289: 0 | AY289: 1170405
... A545: Puducherry | C545: 543 | D545: 31 | E545: Puducherry | F545: 2014 | H545: 255826 | I545: 194972 | J545: 132657 | K545: 60580 | L545: 22754 | M545: 22268 | N545: 12709 | O545: 8307 | P545: 5896 | Q545: 3472 | R545: 2494 | S545: 2060 | T545: 1777 | U545: 1726 | V545: 1442 | W545: 1340 | X545: 1270 | Y545: 1236 | Z545: 1144 | AA545: 767 | AB545: 747 | AC545: 746 | AD545: 610 | AE545: 497 | AF545: 477 | AG545: 467 | AH545: 465 | AI545: 438 | AJ545: 366 | AK545: 309 | AL545: 198 | AM545: 0 | AN545: 0 | AO545: 0 | AP545: 0 | AQ545: 0 | AR545: 0 | AS545: 0 | AT545: 0 | AU545: 0 | AV545: 0 | AW545: 0 | AX545: 0 | AY545: 740017

Sheet OWNCM_lim
A1: OWNCM_PCP
A2: 3 candidates
B3: A’s | C3: vote | D3: share | E3: lower | F3: limit | G3: 0.3889 | I3: A’s | J3: vote | K3: share | L3: upper | M3: limit | N3: 0.4722
B5: B’s | C5: vote | D5: share | E5: lower | F5: limit | G5: 0.3056 | I5: B’s | J5: vote | K5: share | L5: upper | M5: limit | N5: 0.4306
B7: C’s | C7: vote | D7: share | E7: lower | F7: limit | G7: 0.0972 | I7: C’s | J7: vote | K7: share | L7: upper | M7: limit | N7: 0.2639
C10: G | D10: 0.5 | E10: 0.25 | F10: 0.25
C11: I | D11: =17/36 -> 0.47222222 | E11: =11/36 -> 0.30555556 | F11: =2/9 -> 0.22222222
C12: D | D12: 0.5 | E12: 0.5 | F12: 0
C13: K | D13: =17/36 -> 0.47222222 | E13: =31/72 -> 0.43055556 | F13: =7/72 -> 0.097222222
A14: WPCW
A15: 3 candidates
B16: A’s | C16: vote | D16: share | E16: lower | F16: limit | G16: =MIN(D10:D13) -> 0.47222222 | I16: A’s | J16: vote | K16: share | L16: upper | M16: limit | N16: =MAX(D10:D13) -> 0.5
B18: B’s | C18: vote | D18: share | E18: lower | F18: limit | G18: =MIN(E10:E13) -> 0.25 | I18: B’s | J18: vote | K18: share | L18: upper | M18: limit | N18: =MAX(E10:E13) -> 0.5
B20: C’s | C20: vote | D20: share | E20: lower | F20: limit | G20: =MIN(F10:F13) -> 0 | I20: C’s | J20: vote | K20: share | L20: upper | M20: limit | N20: =MAX(F10:F13) -> 0.25
A23: OWNCM_PCP
A24: 4 candidates
B25: Case - a) - A + D > B+C
B26: A’s | C26: vote | D26: share | E26: lower | F26: limit | G26: 0.3125 | I26: A’s | J26: vote | K26: share | L26: upper | M26: limit | N26: 0.4792
B28: B’s | C28: vote | D28: share | E28: lower | F28: limit | G28: 0.1875 | I28: B’s | J28: vote | K28: share | L28: upper | M28: limit | N28: 0.2431
B30: C’s | C30: vote | D30: share | E30: lower | F30: limit | G30: 0.1493 | I30: C’s | J30: vote | K30: share | L30: upper | M30: limit | N30: 0.2326
B32: D’s | C32: vote | D32: share | E32: lower | F32: limit | G32: 0.0451 | I32: D’s | J32: vote | K32: share | L32: upper | M32: limit | N32: 0.2118
B36: Case - b) - A + D < B+C
B38: A’s | C38: vote | D38: share | E38: lower | F38: limit | G38: 0.2986 | I38: A’s | J38: vote | K38: share | L38: upper | M38: limit | N38: 0.4653
B40: B’s | C40: vote | D40: share | E40: lower | F40: limit | G40: 0.2778 | I40: B’s | J40: vote | K40: share | L40: upper | M40: limit | N40: 0.4444
B42: C’s | C42: vote | D42: share | E42: lower | F42: limit | G42: 0.0694 | I42: C’s | J42: vote | K42: share | L42: upper | M42: limit | N42: 0.2917
B44: D’s | C44: vote | D44: share | E44: lower | F44: limit | G44: 0.0208 | I44: D’s | J44: vote | K44: share | L44: upper | M44: limit | N44: 0.1875
A47: WPCW
A48: 4 candidates | B48: Case - a) - A + D > B+C
C49: Given by the volume captured by:
B51: From Fig. 2.1 or 3rd fig of Santanu Sir's 7-pg pdf draft of 13062017 | C51: X'' | D51: X' | E51: i.e. | G51: 0.47872 | H51: 0.242909 | I51: 0.14981 | J51: 0.128545 | K51: and | L51: =1/2 -> 0.5 | M51: 0.25 | N51: =1/8 -> 0.125 | O51: =N51 -> 0.125
C52: Y'' | D52: Y' | G52: 0.47872 | H52: 0.18793 | I52: 0.1773 | J52: 0.15603 | L52: =0.5 -> 0.5 | M52: =1/6 -> 0.16666667 | N52: =M52 -> 0.16666667 | O52: =N52 -> 0.16666667
C53: B''C" | D53: B'C' | G53: 0.47872804 | H53: 0.24290935 | I53: 0.23227336 | J53: 0.046089252 | L53: 0.5 | M53: 0.25 | N53: 0.25 | O53: 0
F55: Min | G55: =MIN(G51:G53,L51:L53) -> 0.47872 | H55: =MIN(H51:H53,M51:M53) -> 0.16666667 | I55: =MIN(I51:I53,N51:N53) -> 0.125 | J55: =MIN(J51:J53,O51:O53) -> 0
F56: Max | G56: =MAX(G51:G53,L51:L53) -> 0.5 | H56: =MAX(H51:H53,M51:M53) -> 0.25 | I56: =MAX(I51:I53,N51:N53) -> 0.25 | J56: =MAX(J51:J53,O51:O53) -> 0.16666667
B59: A’s | C59: vote | D59: share | E59: lower | F59: limit | G59: =G55 -> 0.47872 | I59: A’s | J59: vote | K59: share | L59: upper | M59: limit | N59: =G56 -> 0.5
B61: B’s | C61: vote | D61: share | E61: lower | F61: limit | G61: =H55 -> 0.16666667 | I61: B’s | J61: vote | K61: share | L61: upper | M61: limit | N61: =H56 -> 0.25
B63: C’s | C63: vote | D63: share | E63: lower | F63: limit | G63: =I55 -> 0.125 | I63: C’s | J63: vote | K63: share | L63: upper | M63: limit | N63: =I56 -> 0.25
B65: D’s | C65: vote | D65: share | E65: lower | F65: limit | G65: =J55 -> 0 | I65: D’s | J65: vote | K65: share | L65: upper | M65: limit | N65: =J56 -> 0.16666667
B69: Case - b) - A + D < B+C
C70: Given by the volume captured by:
...

Sheet 4 candidates_LS-2014
H1: 0 | I1: 1 | J1: 2 | K1: 3 | L1: 4 | M1: 5 | N1: 6 | O1: 7 | P1: 8 | Q1: 9 | R1: 10 | S1: 11 | T1: 12 | U1: 13 | V1: 14 | W1: 15 | X1: 16 | Y1: 17 | Z1: 18 | AA1: 19 | AB1: 20 | AC1: 21 | AD1: 22 | AE1: 23 | AF1: 24 | AG1: 25 | AH1: 26 | AI1: 27 | AJ1: 28 | AK1: 29 | AL1: 30 | AM1: 31 | AN1: 32 | AO1: 33 | AP1: 34 | AQ1: 35 | AR1: 36 | AS1: 37 | AT1: 38 | AU1: 39 | AV1: 40 | AW1: 41 | AX1: 42
A2: state | B2: statecode | C2: constituency_no | D2: No_Candidates | E2: constituency | F2: year | G2: Classification | H2: first | I2: second | J2: third | K2: fourth | L2: fifth | M2: sixth | N2: seventh | O2: eighth | P2: ninth | Q2: tenth | R2: eleventh | S2: twelveth | T2: thirteenth | U2: fourteenth | V2: fifteenth | W2: sixteenth | X2: seventeenth | Y2: eighteenth | Z2: nineteenth | AA2: twentieth | AB2: twentyfirst | AC2: twentysecond | AD2: twentythird | AE2: twentyfourth | AF2: twentyfifth | AG2: twentysixth | AH2: twentyseventh | AI2: twentyeighth | AJ2: twentyninth | AK2: thirtieth | AL2: thirtyfirst | AM2: thirtysecond | AN2: thirtythird | AO2: thirtyfourth | AP2: thirtyfifth | AQ2: thirtysixth | AR2: thirtyseventh | AS2: thirtyeightth | AT2: thirtyninth | AU2: fortieth | AV2: fortyfirst | AW2: fortysecond | AX2: fortythird | AY2: total | AZ2: Winner_vote_share | BA2: Flag_1 | BB2: A_share | BC2: B_share | BD2: C_share | BE2: D_share | BF2: A+D > B+C | BG2: A+D <= B+C | BH2: OWNCM_PCP | BI2: WPCW - case A | BJ2: WPCW - case B | BK2: WPCW | BL2: PBP
A3: Andhra Pradesh | C3: 1 | D3: 9 | E3: Adilabad | F3: 2014 | H3: 430847 | I3: 259557 | J3: 184198 | K3: 94420 | L3: 41032 | M3: 17084 | N3: 8859 | O3: 5055 | P3: 4787 | Q3: 0 | R3: 0 | S3: 0 | T3: 0 | U3: 0 | V3: 0 | W3: 0 | X3: 0 | Y3: 0 | Z3: 0 | AA3: 0 | AB3: 0 | AC3: 0 | AD3: 0 | AE3: 0 | AF3: 0 | AG3: 0 | AH3: 0 | AI3: 0 | AJ3: 0 | AK3: 0 | AL3: 0 | AM3: 0 | AN3: 0 | AO3: 0 | AP3: 0 | AQ3: 0 | AR3: 0 | AS3: 0 | AT3: 0 | AU3: 0 | AV3: 0 | AW3: 0 | AX3: 0 | AY3: 1045839
A4: Andhra Pradesh | C4: 2 | D4: 18 | E4: Peddapalle | F4: 2014 | H4: 565496 | I4: 274338 | J4: 63334 | K4: 45977 | L4: 9449 | M4: 9290 | N4: 9199 | O4: 8609 | P4: 7258 | Q4: 5361 | R4: 3866 | S4: 3699 | T4: 3266 | U4: 3020 | V4: 2742 | W4: 2674 | X4: 2361 | Y4: 2245 | Z4: 0 | AA4: 0 | AB4: 0 | AC4: 0 | AD4: 0 | AE4: 0 | AF4: 0 | AG4: 0 | AH4: 0 | AI4: 0 | AJ4: 0 | AK4: 0 | AL4: 0 | AM4: 0 | AN4: 0 | AO4: 0 | AP4: 0 | AQ4: 0 | AR4: 0 | AS4: 0 | AT4: 0 | AU4: 0 | AV4: 0 | AW4: 0 | AX4: 0 | AY4: 1022184
A5: Andhra Pradesh | C5: 3 | D5: 18 | E5: Karimnagar | F5: 2014 | H5: 505358 | I5: 300706 | J5: 214828 | K5: 39308 | L5: 11328 | M5: 8034 | N5: 6713 | O5: 5734 | P5: 4769 | Q5: 4728 | R5: 3943 | S5: 3851 | T5: 3772 | U5: 3075 | V5: 2757 | W5: 2445 | X5: 2062 | Y5: 1773 | Z5: 0 | AA5: 0 | AB5: 0 | AC5: 0 | AD5: 0 | AE5: 0 | AF5: 0 | AG5: 0 | AH5: 0 | AI5: 0 | AJ5: 0 | AK5: 0 | AL5: 0 | AM5: 0 | AN5: 0 | AO5: 0 | AP5: 0 | AQ5: 0 | AR5: 0 | AS5: 0 | AT5: 0 | AU5: 0 | AV5: 0 | AW5: 0 | AX5: 0 | AY5: 1125184
A6: Andhra Pradesh | C6: 4 | D6: 17 | E6: Nizamabad | F6: 2014 | H6: 439307 | I6: 272123 | J6: 225333 | K6: 43814 | L6: 8129 | M6: 7421 | N6: 7266 | O6: 4791 | P6: 3990 | Q6: 3651 | R6: 3529 | S6: 3091 | T6: 2817 | U6: 2621 | V6: 2462 | W6: 1978 | X6: 1601 | Y6: 0 | Z6: 0 | AA6: 0 | AB6: 0 | AC6: 0 | AD6: 0 | AE6: 0 | AF6: 0 | AG6: 0 | AH6: 0 | AI6: 0 | AJ6: 0 | AK6: 0 | AL6: 0 | AM6: 0 | AN6: 0 | AO6: 0 | AP6: 0 | AQ6: 0 | AR6: 0 | AS6: 0 | AT6: 0 | AU6: 0 | AV6: 0 | AW6: 0 | AX6: 0 | AY6: 1033924
A7: Andhra Pradesh | C7: 5 | D7: 11 | E7: Zahirabad | F7: 2014 | H7: 508661 | I7: 364030 | J7: 157497 | K7: 18027 | L7: 12383 | M7: 11190 | N7: 8180 | O7: 4804 | P7: 4426 | Q7: 3285 | R7: 2323 | S7: 0 | T7: 0 | U7: 0 | V7: 0 | W7: 0 | X7: 0 | Y7: 0 | Z7: 0 | AA7: 0 | AB7: 0 | AC7: 0 | AD7: 0 | AE7: 0 | AF7: 0 | AG7: 0 | AH7: 0 | AI7: 0 | AJ7: 0 | AK7: 0 | AL7: 0 | AM7: 0 | AN7: 0 | AO7: 0 | AP7: 0 | AQ7: 0 | AR7: 0 | AS7: 0 | AT7: 0 | AU7: 0 | AV7: 0 | AW7: 0 | AX7: 0 | AY7: 1094806
A8: Andhra Pradesh | C8: 6 | D8: 14 | E8: Medak | F8: 2014 | H8: 657492 | I8: 260463 | J8: 181804 | K8: 33507 | L8: 11752 | M8: 10696 | N8: 7599 | O8: 6643 | P8: 5010 | Q8: 4441 | R8: 3297 | S8: 3281 | T8: 2973 | U8: 2053 | V8: 0 | W8: 0 | X8: 0 | Y8: 0 | Z8: 0 | AA8: 0 | AB8: 0 | AC8: 0 | AD8: 0 | AE8: 0 | AF8: 0 | AG8: 0 | AH8: 0 | AI8: 0 | AJ8: 0 | AK8: 0 | AL8: 0 | AM8: 0 | AN8: 0 | AO8: 0 | AP8: 0 | AQ8: 0 | AR8: 0 | AS8: 0 | AT8: 0 | AU8: 0 | AV8: 0 | AW8: 0 | AX8: 0 | AY8: 1191011
A9: Andhra Pradesh | C9: 7 | D9: 31 | E9: Malkajgiri | F9: 2014 | H9: 523356 | I9: 495190 | J9: 233530 | K9: 158248 | L9: 115221 | M9: 18544 | N9: 13239 | O9: 8692 | P9: 8301 | Q9: 7953 | R9: 6133 | S9: 5717 | T9: 4095 | U9: 2677 | V9: 2261 | W9: 2049 | X9: 1693 | Y9: 1547 | Z9: 1416 | AA9: 1390 | AB9: 1325 | AC9: 1301 | AD9: 1032 | AE9: 1026 | AF9: 899 | AG9: 802 | AH9: 775 | AI9: 596 | AJ9: 529 | AK9: 496 | AL9: 411 | AM9: 0 | AN9: 0 | AO9: 0 | AP9: 0 | AQ9: 0 | AR9: 0 | AS9: 0 | AT9: 0 | AU9: 0 | AV9: 0 | AW9: 0 | AX9: 0 | AY9: 1620444
A10: Andhra Pradesh | C10: 8 | D10: 31 | E10: Secundrabad | F10: 2014 | H10: 438271 | I10: 183536 | J10: 145120 | K10: 143847 | L10: 45187 | M10: 11184 | N10: 6572 | O10: 3691 | P10: 2863 | Q10: 2603 | R10: 2481 | S10: 2311 | T10: 2058 | U10: 1813 | V10: 1496 | W10: 1144 | X10: 959 | Y10: 928 | Z10: 886 | AA10: 873 | AB10: 809 | AC10: 786 | AD10: 779 | AE10: 638 | AF10: 554 | AG10: 547 | AH10: 474 | AI10: 376 | AJ10: 370 | AK10: 322 | AL10: 291 | AM10: 0 | AN10: 0 | AO10: 0 | AP10: 0 | AQ10: 0 | AR10: 0 | AS10: 0 | AT10: 0 | AU10: 0 | AV10: 0 | AW10: 0 | AX10: 0 | AY10: 1003769
A11: Andhra Pradesh | C11: 9 | D11: 17 | E11: Hyderbad | F11: 2014 | H11: 513868 | I11: 311414 | J11: 49310 | K11: 37195 | L11: 21796 | M11: 10743 | N11: 6118 | O11: 5992 | P11: 5013 | Q11: 3100 | R11: 2102 | S11: 1593 | T11: 740 | U11: 728 | V11: 626 | W11: 598 | X11: 485 | Y11: 0 | Z11: 0 | AA11: 0 | AB11: 0 | AC11: 0 | AD11: 0 | AE11: 0 | AF11: 0 | AG11: 0 | AH11: 0 | AI11: 0 | AJ11: 0 | AK11: 0 | AL11: 0 | AM11: 0 | AN11: 0 | AO11: 0 | AP11: 0 | AQ11: 0 | AR11: 0 | AS11: 0 | AT11: 0 | AU11: 0 | AV11: 0 | AW11: 0 | AX11: 0 | AY11: 971421
A12: Andhra Pradesh | C12: 10 | D12: 16 | E12: Chelvella | F12: 2014 | H12: 435077 | I12: 362054 | J12: 353203 | K12: 56835 | L12: 40135 | M12: 24660 | N12: 10018 | O12: 7732 | P12: 7462 | Q12: 5789 | R12: 2904 | S12: 2545 | T12: 2214 | U12: 2058 | V12: 1765 | W12: 1411 | X12: 0 | Y12: 0 | Z12: 0 | AA12: 0 | AB12: 0 | AC12: 0 | AD12: 0 | AE12: 0 | AF12: 0 | AG12: 0 | AH12: 0 | AI12: 0 | AJ12: 0 | AK12: 0 | AL12: 0 | AM12: 0 | AN12: 0 | AO12: 0 | AP12: 0 | AQ12: 0 | AR12: 0 | AS12: 0 | AT12: 0 | AU12: 0 | AV12: 0 | AW12: 0 | AX12: 0 | AY12: 1315862
A13: Andhra Pradesh | C13: 11 | D13: 10 | E13: Mahbubnagar | F13: 2014 | H13: 334228 | I13: 331638 | J13: 272791 | K13: 30388 | L13: 15779 | M13: 9105 | N13: 9037 | O13: 4549 | P13: 4033 | Q13: 3252 | R13: 0 | S13: 0 | T13: 0 | U13: 0 | V13: 0 | W13: 0 | X13: 0 | Y13: 0 | Z13: 0 | AA13: 0 | AB13: 0 | AC13: 0 | AD13: 0 | AE13: 0 | AF13: 0 | AG13: 0 | AH13: 0 | AI13: 0 | AJ13: 0 | AK13: 0 | AL13: 0 | AM13: 0 | AN13: 0 | AO13: 0 | AP13: 0 | AQ13: 0 | AR13: 0 | AS13: 0 | AT13: 0 | AU13: 0 | AV13: 0 | AW13: 0 | AX13: 0 | AY13: 1014800
A14: Andhra Pradesh | C14: 12 | D14: 7 | E14: Nagarkurnool | F14: 2014 | H14: 420075 | I14: 403399 | J14: 183352 | K14: 54680 | L14: 22985 | M14: 12388 | N14: 12089 | O14: 0 | P14: 0 | Q14: 0 | R14: 0 | S14: 0 | T14: 0 | U14: 0 | V14: 0 | W14: 0 | X14: 0 | Y14: 0 | Z14: 0 | AA14: 0 | AB14: 0 | AC14: 0 | AD14: 0 | AE14: 0 | AF14: 0 | AG14: 0 | AH14: 0 | AI14: 0 | AJ14: 0 | AK14: 0 | AL14: 0 | AM14: 0 | AN14: 0 | AO14: 0 | AP14: 0 | AQ14: 0 | AR14: 0 | AS14: 0 | AT14: 0 | AU14: 0 | AV14: 0 | AW14: 0 | AX14: 0 | AY14: 1108968
... A45: Arunachal Pradesh | C45: 43 | D45: 9 | E45: Arunachal West | F45: 2014 | H45: 169367 | I45: 127629 | J45: 14664 | K45: 9135 | L45: 6065 | M45: 3647 | N45: 2362 | O45: 1816 | P45: 980 | Q45: 0 | R45: 0 | S45: 0 | T45: 0 | U45: 0 | V45: 0 | W45: 0 | X45: 0 | Y45: 0 | Z45: 0 | AA45: 0 | AB45: 0 | AC45: 0 | AD45: 0 | AE45: 0 | AF45: 0 | AG45: 0 | AH45: 0 | AI45: 0 | AJ45: 0 | AK45: 0 | AL45: 0 | AM45: 0 | AN45: 0 | AO45: 0 | AP45: 0 | AQ45: 0 | AR45: 0 | AS45: 0 | AT45: 0 | AU45: 0 | AV45: 0 | AW45: 0 | AX45: 0 | AY45: 335665
A46: Arunachal Pradesh | C46: 44 | D46: 4 | E46: Arunachal East | F46: 2014 | G46: =IF(BH46,"OWNCM",IF(BK46,"WPCW","PBP")) -> WPCW | H46: 118455 | I46: 105977 | J46: 32354 | K46: 4505 | L46: 0 | M46: 0 | N46: 0 | O46: 0 | P46: 0 | Q46: 0 | R46: 0 | S46: 0 | T46: 0 | U46: 0 | V46: 0 | W46: 0 | X46: 0 | Y46: 0 | Z46: 0 | AA46: 0 | AB46: 0 | AC46: 0 | AD46: 0 | AE46: 0 | AF46: 0 | AG46: 0 | AH46: 0 | AI46: 0 | AJ46: 0 | AK46: 0 | AL46: 0 | AM46: 0 | AN46: 0 | AO46: 0 | AP46: 0 | AQ46: 0 | AR46: 0 | AS46: 0 | AT46: 0 | AU46: 0 | AV46: 0 | AW46: 0 | AX46: 0 | AY46: 261291 | AZ46: =MAX(H46:K46)/AY46 -> 0.45334512 | BA46: =IF(AZ46<50%,1,0) -> 1 | BB46: =H46/$AY46 -> 0.45334512 | BC46: =I46/$AY46 -> 0.40558994 | BD46: =J46/$AY46 -> 0.12382363 | BE46: =K46/$AY46 -> 0.017241313 | BF46: =IF((BB46+BE46)>(BC46+BD46),1,0) -> 0 | BG46: =IF(BF46=1,0,1) -> 1 | BH46: =IF(BF46,IF(AND('4 candidates_LS-2014'!BB46>OWNCM_lim!$G$26,'4 candidates_LS-2014'!BB46<=OWNCM_lim!$N$26,'4 candidates_LS-2014'!BC46>OWNCM_lim!$G$28,'4 candidates_LS-2014'!BC46<=OWNCM_lim!$N$28,'4 candidates_LS-2014'!BD46>OWNCM_lim!$G$30,'4 candidates_LS-2014'!BD46<=OWNCM_lim!$N$30,'4 candidates_LS-2014'!BE46>OWNCM_lim!$G$32,'4 candidates_LS-2014'!BE46<=OWNCM_lim!$N$32),1,0),IF(AND('4 candidates_LS-2014'!BB46>OWNCM_lim!$G$38,'4 candidates_LS-2014'!BB46<=OWNCM_lim!$N$38,'4 candidates_LS-2014'!BC46>OWNCM_lim!$G$40,'4 candidates_LS-2014'!BC46<=OWNCM_lim!$N$40,'4 candidates_LS-2014'!BD46>OWNCM_lim!$G$42,'4 candidates_LS-2014'!BD46<=OWNCM_lim!$N$42,'4 candidates_LS-2014'!BE46>OWNCM_lim!$G$44,'4 candidates_LS-2014'!BE46<=OWNCM_lim!$N$44),1,0)) -> 0 | BI46: =IF(BH46,0,IF(AND(BB46>OWNCM_lim!$G$59,'4 candidates_LS-2014'!BB46<=OWNCM_lim!$N$59,'4 candidates_LS-2014'!BC46>OWNCM_lim!$G$61,'4 candidates_LS-2014'!BC46<=OWNCM_lim!$N$61,'4 candidates_LS-2014'!BD46>OWNCM_lim!$G$63,'4 candidates_LS-2014'!BD46<=OWNCM_lim!$N$63,'4 candidates_LS-2014'!BE46>OWNCM_lim!$G$65,'4 candidates_LS-2014'!BE46<=OWNCM_lim!$N$65),1,0)) -> 0 | BJ46: =IF(BH46,0,IF(AND(BB46>OWNCM_lim!$G$80,'4 candidates_LS-2014'!BB46<=OWNCM_lim!$N$80,'4 candidates_LS-2014'!BC46>OWNCM_lim!$G$82,'4 candidates_LS-2014'!BC46<=OWNCM_lim!$N$82,'4 candidates_LS-2014'!BD46>OWNCM_lim!$G$84,'4 candidates_LS-2014'!BD46<=OWNCM_lim!$N$84,'4 candidates_LS-2014'!BE46>OWNCM_lim!$G$86,'4 candidates_LS-2014'!BE46<=OWNCM_lim!$N$86),1,0)) -> 1 | BK46: =IF(BH46=0,IF(BI46=1,1,IF(BJ46=1,1,0))) -> 1 | BL46: =IF(AND(BH46=0,BK46=0),1,0) -> 0
A47: Assam | C47: 45 | D47: 16 | E47: Karimganj | F47: 2014 | H47: 362866 | I47: 260772 | J47: 226562 | K47: 5556 | L47: 4266 | M47: 3658 | N47: 3437 | O47: 3114 | P47: 2465 | Q47: 2447 | R47: 2392 | S47: 2275 | T47: 1974 | U47: 1880 | V47: 1664 | W47: 1592 | X47: 0 | Y47: 0 | Z47: 0 | AA47: 0 | AB47: 0 | AC47: 0 | AD47: 0 | AE47: 0 | AF47: 0 | AG47: 0 | AH47: 0 | AI47: 0 | AJ47: 0 | AK47: 0 | AL47: 0 | AM47: 0 | AN47: 0 | AO47: 0 | AP47: 0 | AQ47: 0 | AR47: 0 | AS47: 0 | AT47: 0 | AU47: 0 | AV47: 0 | AW47: 0 | AX47: 0 | AY47: 886920
A48: Assam | C48: 46 | D48: 18 | E48: Silchar | F48: 2014 | H48: 336451 | I48: 301210 | J48: 85530 | K48: 12460 | L48: 8595 | M48: 8577 | N48: 8282 | O48: 7679 | P48: 6221 | Q48: 4310 | R48: 3347 | S48: 3151 | T48: 3118 | U48: 2740 | V48: 2462 | W48: 2170 | X48: 1922 | Y48: 1605 | Z48: 0 | AA48: 0 | AB48: 0 | AC48: 0 | AD48: 0 | AE48: 0 | AF48: 0 | AG48: 0 | AH48: 0 | AI48: 0 | AJ48: 0 | AK48: 0 | AL48: 0 | AM48: 0 | AN48: 0 | AO48: 0 | AP48: 0 | AQ48: 0 | AR48: 0 | AS48: 0 | AT48: 0 | AU48: 0 | AV48: 0 | AW48: 0 | AX48: 0 | AY48: 799830
A49: Assam | C49: 47 | D49: 6 | E49: Autonomous District | F49: 2014 | H49: 213152 | I49: 189057 | J49: 108299 | K49: 11762 | L49: 11747 | M49: 9263 | N49: 0 | O49: 0 | P49: 0 | Q49: 0 | R49: 0 | S49: 0 | T49: 0 | U49: 0 | V49: 0 | W49: 0 | X49: 0 | Y49: 0 | Z49: 0 | AA49: 0 | AB49: 0 | AC49: 0 | AD49: 0 | AE49: 0 | AF49: 0 | AG49: 0 | AH49: 0 | AI49: 0 | AJ49: 0 | AK49: 0 | AL49: 0 | AM49: 0 | AN49: 0 | AO49: 0 | AP49: 0 | AQ49: 0 | AR49: 0 | AS49: 0 | AT49: 0 | AU49: 0 | AV49: 0 | AW49: 0 | AX49: 0 | AY49: 543280
A50: Assam | C50: 48 | D50: 16 | E50: Dhubri | F50: 2014 | H50: 592569 | I50: 362839 | J50: 298985 | K50: 40208 | L50: 23816 | M50: 9897 | N50: 7874 | O50: 5935 | P50: 5811 | Q50: 4607 | R50: 4468 | S50: 3277 | T50: 2785 | U50: 2723 | V50: 2375 | W50: 1455 | X50: 0 | Y50: 0 | Z50: 0 | AA50: 0 | AB50: 0 | AC50: 0 | AD50: 0 | AE50: 0 | AF50: 0 | AG50: 0 | AH50: 0 | AI50: 0 | AJ50: 0 | AK50: 0 | AL50: 0 | AM50: 0 | AN50: 0 | AO50: 0 | AP50: 0 | AQ50: 0 | AR50: 0 | AS50: 0 | AT50: 0 | AU50: 0 | AV50: 0 | AW50: 0 | AX50: 0 | AY50: 1369624
A51: Assam | C51: 49 | D51: 7 | E51: Kokrajhar | F51: 2014 | H51: 634428 | I51: 278649 | J51: 243759 | K51: 20074 | L51: 18183 | M51: 17537 | N51: 11239 | O51: 0 | P51: 0 | Q51: 0 | R51: 0 | S51: 0 | T51: 0 | U51: 0 | V51: 0 | W51: 0 | X51: 0 | Y51: 0 | Z51: 0 | AA51: 0 | AB51: 0 | AC51: 0 | AD51: 0 | AE51: 0 | AF51: 0 | AG51: 0 | AH51: 0 | AI51: 0 | AJ51: 0 | AK51: 0 | AL51: 0 | AM51: 0 | AN51: 0 | AO51: 0 | AP51: 0 | AQ51: 0 | AR51: 0 | AS51: 0 | AT51: 0 | AU51: 0 | AV51: 0 | AW51: 0 | AX51: 0 | AY51: 1223869
A52: Assam | C52: 50 | D52: 16 | E52: Barpeta | F52: 2014 | H52: 394702 | I52: 352361 | J52: 277802 | K52: 73733 | L52: 27575 | M52: 24444 | N52: 20135 | O52: 10944 | P52: 5710 | Q52: 4785 | R52: 3433 | S52: 3099 | T52: 1937 | U52: 1859 | V52: 1695 | W52: 1649 | X52: 0 | Y52: 0 | Z52: 0 | AA52: 0 | AB52: 0 | AC52: 0 | AD52: 0 | AE52: 0 | AF52: 0 | AG52: 0 | AH52: 0 | AI52: 0 | AJ52: 0 | AK52: 0 | AL52: 0 | AM52: 0 | AN52: 0 | AO52: 0 | AP52: 0 | AQ52: 0 | AR52: 0 | AS52: 0 | AT52: 0 | AU52: 0 | AV52: 0 | AW52: 0 | AX52: 0 | AY52: 1205863
A53: Assam | C53: 51 | D53: 19 | E53: Gauhati | F53: 2014 | H53: 764985 | I53: 449201 | J53: 137254 | K53: 86546 | L53: 12432 | M53: 8162 | N53: 7345 | O53: 6720 | P53: 6636 | Q53: 5782 | R53: 4809 | S53: 3540 | T53: 3240 | U53: 2845 | V53: 2629 | W53: 2532 | X53: 2411 | Y53: 2385 | Z53: 2275 | AA53: 0 | AB53: 0 | AC53: 0 | AD53: 0 | AE53: 0 | AF53: 0 | AG53: 0 | AH53: 0 | AI53: 0 | AJ53: 0 | AK53: 0 | AL53: 0 | AM53: 0 | AN53: 0 | AO53: 0 | AP53: 0 | AQ53: 0 | AR53: 0 | AS53: 0 | AT53: 0 | AU53: 0 | AV53: 0 | AW53: 0 | AX53: 0 | AY53: 1511729
A54: Assam | C54: 52 | D54: 13 | E54: Mangaldoi | F54: 2014 | H54: 486357 | I54: 463473 | J54: 86347 | K54: 74710 | L54: 66467 | M54: 12443 | N54: 10722 | O54: 8341 | P54: 7600 | Q54: 5531 | R54: 4164 | S54: 3658 | T54: 3424 | U54: 0 | V54: 0 | W54: 0 | X54: 0 | Y54: 0 | Z54: 0 | AA54: 0 | AB54: 0 | AC54: 0 | AD54: 0 | AE54: 0 | AF54: 0 | AG54: 0 | AH54: 0 | AI54: 0 | AJ54: 0 | AK54: 0 | AL54: 0 | AM54: 0 | AN54: 0 | AO54: 0 | AP54: 0 | AQ54: 0 | AR54: 0 | AS54: 0 | AT54: 0 | AU54: 0 | AV54: 0 | AW54: 0 | AX54: 0 | AY54: 1233237
A55: Assam | C55: 53 | D55: 10 | E55: Tezpur | F55: 2014 | H55: 446511 | I55: 360491 | J55: 62730 | K55: 40489 | L55: 24910 | M55: 16667 | N55: 10725 | O55: 8712 | P55: 5207 | Q55: 4246 | R55: 0 | S55: 0 | T55: 0 | U55: 0 | V55: 0 | W55: 0 | X55: 0 | Y55: 0 | Z55: 0 | AA55: 0 | AB55: 0 | AC55: 0 | AD55: 0 | AE55: 0 | AF55: 0 | AG55: 0 | AH55: 0 | AI55: 0 | AJ55: 0 | AK55: 0 | AL55: 0 | AM55: 0 | AN55: 0 | AO55: 0 | AP55: 0 | AQ55: 0 | AR55: 0 | AS55: 0 | AT55: 0 | AU55: 0 | AV55: 0 | AW55: 0 | AX55: 0 | AY55: 980688
A56: Assam | C56: 54 | D56: 9 | E56: Nowgong | F56: 2014 | H56: 494146 | I56: 350587 | J56: 314012 | K56: 35142 | L56: 11325 | M56: 8782 | N56: 6835 | O56: 6462 | P56: 2783 | Q56: 0 | R56: 0 | S56: 0 | T56: 0 | U56: 0 | V56: 0 | W56: 0 | X56: 0 | Y56: 0 | Z56: 0 | AA56: 0 | AB56: 0 | AC56: 0 | AD56: 0 | AE56: 0 | AF56: 0 | AG56: 0 | AH56: 0 | AI56: 0 | AJ56: 0 | AK56: 0 | AL56: 0 | AM56: 0 | AN56: 0 | AO56: 0 | AP56: 0 | AQ56: 0 | AR56: 0 | AS56: 0 | AT56: 0 | AU56: 0 | AV56: 0 | AW56: 0 | AX56: 0 | AY56: 1230074
A57: Assam | C57: 55 | D57: 14 | E57: Kaliabor | F57: 2014 | H57: 443315 | I57: 349441 | J57: 231295 | K57: 78132 | L57: 12403 | M57: 9583 | N57: 9133 | O57: 8271 | P57: 6538 | Q57: 5433 | R57: 4985 | S57: 2966 | T57: 2584 | U57: 2411 | V57: 0 | W57: 0 | X57: 0 | Y57: 0 | Z57: 0 | AA57: 0 | AB57: 0 | AC57: 0 | AD57: 0 | AE57: 0 | AF57: 0 | AG57: 0 | AH57: 0 | AI57: 0 | AJ57: 0 | AK57: 0 | AL57: 0 | AM57: 0 | AN57: 0 | AO57: 0 | AP57: 0 | AQ57: 0 | AR57: 0 | AS57: 0 | AT57: 0 | AU57: 0 | AV57: 0 | AW57: 0 | AX57: 0 | AY57: 1166490
A58: Assam | C58: 56 | D58: 11 | E58: Jorhat | F58: 2014 | H58: 456420 | I58: 354000 | J58: 46626 | K58: 28930 | L58: 14648 | M58: 7331 | N58: 5759 | O58: 5754 | P58: 4737 | Q58: 3659 | R58: 3472 | S58: 0 | T58: 0 | U58: 0 | V58: 0 | W58: 0 | X58: 0 | Y58: 0 | Z58: 0 | AA58: 0 | AB58: 0 | AC58: 0 | AD58: 0 | AE58: 0 | AF58: 0 | AG58: 0 | AH58: 0 | AI58: 0 | AJ58: 0 | AK58: 0 | AL58: 0 | AM58: 0 | AN58: 0 | AO58: 0 | AP58: 0 | AQ58: 0 | AR58: 0 | AS58: 0 | AT58: 0 | AU58: 0 | AV58: 0 | AW58: 0 | AX58: 0 | AY58: 931336
... A277: Meghalaya | C277: 275 | D277: 3 | E277: Tura | F277: 2014 | H277: 239301 | I277: 199585 | J277: 19185 | K277: 0 | L277: 0 | M277: 0 | N277: 0 | O277: 0 | P277: 0 | Q277: 0 | R277: 0 | S277: 0 | T277: 0 | U277: 0 | V277: 0 | W277: 0 | X277: 0 | Y277: 0 | Z277: 0 | AA277: 0 | AB277: 0 | AC277: 0 | AD277: 0 | AE277: 0 | AF277: 0 | AG277: 0 | AH277: 0 | AI277: 0 | AJ277: 0 | AK277: 0 | AL277: 0 | AM277: 0 | AN277: 0 | AO277: 0 | AP277: 0 | AQ277: 0 | AR277: 0 | AS277: 0 | AT277: 0 | AU277: 0 | AV277: 0 | AW277: 0 | AX277: 0 | AY277: 458071
A278: Mizoram | C278: 276 | D278: 4 | E278: Mizoram | F278: 2014 | G278: =IF(BH278,"OWNCM",IF(BK278,"WPCW","PBP")) -> WPCW | H278: 210485 | I278: 204331 | J278: 11890 | K278: 6495 | L278: 0 | M278: 0 | N278: 0 | O278: 0 | P278: 0 | Q278: 0 | R278: 0 | S278: 0 | T278: 0 | U278: 0 | V278: 0 | W278: 0 | X278: 0 | Y278: 0 | Z278: 0 | AA278: 0 | AB278: 0 | AC278: 0 | AD278: 0 | AE278: 0 | AF278: 0 | AG278: 0 | AH278: 0 | AI278: 0 | AJ278: 0 | AK278: 0 | AL278: 0 | AM278: 0 | AN278: 0 | AO278: 0 | AP278: 0 | AQ278: 0 | AR278: 0 | AS278: 0 | AT278: 0 | AU278: 0 | AV278: 0 | AW278: 0 | AX278: 0 | AY278: 433201 | AZ278: =MAX(H278:K278)/AY278 -> 0.485883 | BA278: =IF(AZ278<50%,1,0) -> 1 | BB278: =H278/$AY278 -> 0.485883 | BC278: =I278/$AY278 -> 0.47167712 | BD278: =J278/$AY278 -> 0.027446843 | BE278: =K278/$AY278 -> 0.01499304 | BF278: =IF((BB278+BE278)>(BC278+BD278),1,0) -> 1 | BG278: =IF(BF278=1,0,1) -> 0 | BH278: =IF(BF278,IF(AND('4 candidates_LS-2014'!BB278>OWNCM_lim!$G$26,'4 candidates_LS-2014'!BB278<=OWNCM_lim!$N$26,'4 candidates_LS-2014'!BC278>OWNCM_lim!$G$28,'4 candidates_LS-2014'!BC278<=OWNCM_lim!$N$28,'4 candidates_LS-2014'!BD278>OWNCM_lim!$G$30,'4 candidates_LS-2014'!BD278<=OWNCM_lim!$N$30,'4 candidates_LS-2014'!BE278>OWNCM_lim!$G$32,'4 candidates_LS-2014'!BE278<=OWNCM_lim!$N$32),1,0),IF(AND('4 candidates_LS-2014'!BB278>OWNCM_lim!$G$38,'4 candidates_LS-2014'!BB278<=OWNCM_lim!$N$38,'4 candidates_LS-2014'!BC278>OWNCM_lim!$G$40,'4 candidates_LS-2014'!BC278<=OWNCM_lim!$N$40,'4 candidates_LS-2014'!BD278>OWNCM_lim!$G$42,'4 candidates_LS-2014'!BD278<=OWNCM_lim!$N$42,'4 candidates_LS-2014'!BE278>OWNCM_lim!$G$44,'4 candidates_LS-2014'!BE278<=OWNCM_lim!$N$44),1,0)) -> 0 | BI278: =IF(BH278,0,IF(AND(BB278>OWNCM_lim!$G$59,'4 candidates_LS-2014'!BB278<=OWNCM_lim!$N$59,'4 candidates_LS-2014'!BC278>OWNCM_lim!$G$61,'4 candidates_LS-2014'!BC278<=OWNCM_lim!$N$61,'4 candidates_LS-2014'!BD278>OWNCM_lim!$G$63,'4 candidates_LS-2014'!BD278<=OWNCM_lim!$N$63,'4 candidates_LS-2014'!BE278>OWNCM_lim!$G$65,'4 candidates_LS-2014'!BE278<=OWNCM_lim!$N$65),1,0)) -> 0 | BJ278: =IF(BH278,0,IF(AND(BB278>OWNCM_lim!$G$80,'4 candidates_LS-2014'!BB278<=OWNCM_lim!$N$80,'4 candidates_LS-2014'!BC278>OWNCM_lim!$G$82,'4 candidates_LS-2014'!BC278<=OWNCM_lim!$N$82,'4 candidates_LS-2014'!BD278>OWNCM_lim!$G$84,'4 candidates_LS-2014'!BD278<=OWNCM_lim!$N$84,'4 candidates_LS-2014'!BE278>OWNCM_lim!$G$86,'4 candidates_LS-2014'!BE278<=OWNCM_lim!$N$86),1,0)) -> 1 | BK278: =IF(BH278=0,IF(BI278=1,1,IF(BJ278=1,1,0))) -> 1 | BL278: =IF(AND(BH278=0,BK278=0),1,0) -> 0
A279: Nagaland | C279: 277 | D279: 4 | E279: Nagaland | F279: 2014 | G279: =IF(BH279,"OWNCM",IF(BK279,"WPCW","PBP")) -> PBP | H279: 713372 | I279: 313147 | J279: 9695 | K279: 2696 | L279: 0 | M279: 0 | N279: 0 | O279: 0 | P279: 0 | Q279: 0 | R279: 0 | S279: 0 | T279: 0 | U279: 0 | V279: 0 | W279: 0 | X279: 0 | Y279: 0 | Z279: 0 | AA279: 0 | AB279: 0 | AC279: 0 | AD279: 0 | AE279: 0 | AF279: 0 | AG279: 0 | AH279: 0 | AI279: 0 | AJ279: 0 | AK279: 0 | AL279: 0 | AM279: 0 | AN279: 0 | AO279: 0 | AP279: 0 | AQ279: 0 | AR279: 0 | AS279: 0 | AT279: 0 | AU279: 0 | AV279: 0 | AW279: 0 | AX279: 0 | AY279: 1038910 | AZ279: =MAX(H279:K279)/AY279 -> 0.68665428 | BA279: =IF(AZ279<50%,1,0) -> 0 | BB279: =H279/$AY279 -> 0.68665428 | BC279: =I279/$AY279 -> 0.30141879 | BD279: =J279/$AY279 -> 0.0093318959 | BE279: =K279/$AY279 -> 0.0025950275 | BF279: =IF((BB279+BE279)>(BC279+BD279),1,0) -> 1 | BG279: =IF(BF279=1,0,1) -> 0 | BH279: =IF(BF279,IF(AND('4 candidates_LS-2014'!BB279>OWNCM_lim!$G$26,'4 candidates_LS-2014'!BB279<=OWNCM_lim!$N$26,'4 candidates_LS-2014'!BC279>OWNCM_lim!$G$28,'4 candidates_LS-2014'!BC279<=OWNCM_lim!$N$28,'4 candidates_LS-2014'!BD279>OWNCM_lim!$G$30,'4 candidates_LS-2014'!BD279<=OWNCM_lim!$N$30,'4 candidates_LS-2014'!BE279>OWNCM_lim!$G$32,'4 candidates_LS-2014'!BE279<=OWNCM_lim!$N$32),1,0),IF(AND('4 candidates_LS-2014'!BB279>OWNCM_lim!$G$38,'4 candidates_LS-2014'!BB279<=OWNCM_lim!$N$38,'4 candidates_LS-2014'!BC279>OWNCM_lim!$G$40,'4 candidates_LS-2014'!BC279<=OWNCM_lim!$N$40,'4 candidates_LS-2014'!BD279>OWNCM_lim!$G$42,'4 candidates_LS-2014'!BD279<=OWNCM_lim!$N$42,'4 candidates_LS-2014'!BE279>OWNCM_lim!$G$44,'4 candidates_LS-2014'!BE279<=OWNCM_lim!$N$44),1,0)) -> 0 | BI279: =IF(BH279,0,IF(AND(BB279>OWNCM_lim!$G$59,'4 candidates_LS-2014'!BB279<=OWNCM_lim!$N$59,'4 candidates_LS-2014'!BC279>OWNCM_lim!$G$61,'4 candidates_LS-2014'!BC279<=OWNCM_lim!$N$61,'4 candidates_LS-2014'!BD279>OWNCM_lim!$G$63,'4 candidates_LS-2014'!BD279<=OWNCM_lim!$N$63,'4 candidates_LS-2014'!BE279>OWNCM_lim!$G$65,'4 candidates_LS-2014'!BE279<=OWNCM_lim!$N$65),1,0)) -> 0 | BJ279: =IF(BH279,0,IF(AND(BB279>OWNCM_lim!$G$80,'4 candidates_LS-2014'!BB279<=OWNCM_lim!$N$80,'4 candidates_LS-2014'!BC279>OWNCM_lim!$G$82,'4 candidates_LS-2014'!BC279<=OWNCM_lim!$N$82,'4 candidates_LS-2014'!BD279>OWNCM_lim!$G$84,'4 candidates_LS-2014'!BD279<=OWNCM_lim!$N$84,'4 candidates_LS-2014'!BE279>OWNCM_lim!$G$86,'4 candidates_LS-2014'!BE279<=OWNCM_lim!$N$86),1,0)) -> 0 | BK279: =IF(BH279=0,IF(BI279=1,1,IF(BJ279=1,1,0))) -> 0 | BL279: =IF(AND(BH279=0,BK279=0),1,0) -> 1
A280: Orissa | C280: 278 | D280: 9 | E280: Bargarh | F280: 2014 | H280: 383230 | I280: 372052 | J280: 274610 | K280: 26216 | L280: 21100 | M280: 15672 | N280: 14500 | O280: 8009 | P280: 7912 | Q280: 0 | R280: 0 | S280: 0 | T280: 0 | U280: 0 | V280: 0 | W280: 0 | X280: 0 | Y280: 0 | Z280: 0 | AA280: 0 | AB280: 0 | AC280: 0 | AD280: 0 | AE280: 0 | AF280: 0 | AG280: 0 | AH280: 0 | AI280: 0 | AJ280: 0 | AK280: 0 | AL280: 0 | AM280: 0 | AN280: 0 | AO280: 0 | AP280: 0 | AQ280: 0 | AR280: 0 | AS280: 0 | AT280: 0 | AU280: 0 | AV280: 0 | AW280: 0 | AX280: 0 | AY280: 1123301
A281: Orissa | C281: 279 | D281: 13 | E281: Sundargarh | F281: 2014 | H281: 340508 | I281: 321679 | J281: 269335 | K281: 15835 | L281: 9472 | M281: 9460 | N281: 9001 | O281: 8448 | P281: 7429 | Q281: 7282 | R281: 4408 | S281: 3951 | T281: 3903 | U281: 0 | V281: 0 | W281: 0 | X281: 0 | Y281: 0 | Z281: 0 | AA281: 0 | AB281: 0 | AC281: 0 | AD281: 0 | AE281: 0 | AF281: 0 | AG281: 0 | AH281: 0 | AI281: 0 | AJ281: 0 | AK281: 0 | AL281: 0 | AM281: 0 | AN281: 0 | AO281: 0 | AP281: 0 | AQ281: 0 | AR281: 0 | AS281: 0 | AT281: 0 | AU281: 0 | AV281: 0 | AW281: 0 | AX281: 0 | AY281: 1010711
A282: Orissa | C282: 280 | D282: 12 | E282: Sambalpur | F282: 2014 | H282: 358618 | I282: 328042 | J282: 242131 | K282: 13314 | L282: 12211 | M282: 7029 | N282: 4763 | O282: 4502 | P282: 4018 | Q282: 4012 | R282: 3110 | S282: 2559 | T282: 0 | U282: 0 | V282: 0 | W282: 0 | X282: 0 | Y282: 0 | Z282: 0 | AA282: 0 | AB282: 0 | AC282: 0 | AD282: 0 | AE282: 0 | AF282: 0 | AG282: 0 | AH282: 0 | AI282: 0 | AJ282: 0 | AK282: 0 | AL282: 0 | AM282: 0 | AN282: 0 | AO282: 0 | AP282: 0 | AQ282: 0 | AR282: 0 | AS282: 0 | AT282: 0 | AU282: 0 | AV282: 0 | AW282: 0 | AX282: 0 | AY282: 984309
A283: Orissa | C283: 281 | D283: 9 | E283: Keonjhar | F283: 2014 | H283: 434471 | I283: 277154 | J283: 190531 | K283: 101999 | L283: 26065 | M283: 16420 | N283: 16299 | O283: 12236 | P283: 8694 | Q283: 0 | R283: 0 | S283: 0 | T283: 0 | U283: 0 | V283: 0 | W283: 0 | X283: 0 | Y283: 0 | Z283: 0 | AA283: 0 | AB283: 0 | AC283: 0 | AD283: 0 | AE283: 0 | AF283: 0 | AG283: 0 | AH283: 0 | AI283: 0 | AJ283: 0 | AK283: 0 | AL283: 0 | AM283: 0 | AN283: 0 | AO283: 0 | AP283: 0 | AQ283: 0 | AR283: 0 | AS283: 0 | AT283: 0 | AU283: 0 | AV283: 0 | AW283: 0 | AX283: 0 | AY283: 1083869
A284: Orissa | C284: 282 | D284: 10 | E284: Mayurbhanj | F284: 2014 | H284: 393779 | I284: 270913 | J284: 172984 | K284: 142165 | L284: 23517 | M284: 14632 | N284: 12041 | O284: 8183 | P284: 8133 | Q284: 7052 | R284: 0 | S284: 0 | T284: 0 | U284: 0 | V284: 0 | W284: 0 | X284: 0 | Y284: 0 | Z284: 0 | AA284: 0 | AB284: 0 | AC284: 0 | AD284: 0 | AE284: 0 | AF284: 0 | AG284: 0 | AH284: 0 | AI284: 0 | AJ284: 0 | AK284: 0 | AL284: 0 | AM284: 0 | AN284: 0 | AO284: 0 | AP284: 0 | AQ284: 0 | AR284: 0 | AS284: 0 | AT284: 0 | AU284: 0 | AV284: 0 | AW284: 0 | AX284: 0 | AY284: 1053399
A285: Orissa | C285: 283 | D285: 11 | E285: Balasore | F285: 2014 | H285: 433768 | I285: 291943 | J285: 277517 | K285: 14538 | L285: 9856 | M285: 7716 | N285: 4529 | O285: 3240 | P285: 2664 | Q285: 1856 | R285: 1823 | S285: 0 | T285: 0 | U285: 0 | V285: 0 | W285: 0 | X285: 0 | Y285: 0 | Z285: 0 | AA285: 0 | AB285: 0 | AC285: 0 | AD285: 0 | AE285: 0 | AF285: 0 | AG285: 0 | AH285: 0 | AI285: 0 | AJ285: 0 | AK285: 0 | AL285: 0 | AM285: 0 | AN285: 0 | AO285: 0 | AP285: 0 | AQ285: 0 | AR285: 0 | AS285: 0 | AT285: 0 | AU285: 0 | AV285: 0 | AW285: 0 | AX285: 0 | AY285: 1049450
A286: Orissa | C286: 284 | D286: 9 | E286: Bhadrak | F286: 2014 | H286: 502338 | I286: 322979 | J286: 216617 | K286: 11930 | L286: 7607 | M286: 6750 | N286: 5961 | O286: 4518 | P286: 2639 | Q286: 0 | R286: 0 | S286: 0 | T286: 0 | U286: 0 | V286: 0 | W286: 0 | X286: 0 | Y286: 0 | Z286: 0 | AA286: 0 | AB286: 0 | AC286: 0 | AD286: 0 | AE286: 0 | AF286: 0 | AG286: 0 | AH286: 0 | AI286: 0 | AJ286: 0 | AK286: 0 | AL286: 0 | AM286: 0 | AN286: 0 | AO286: 0 | AP286: 0 | AQ286: 0 | AR286: 0 | AS286: 0 | AT286: 0 | AU286: 0 | AV286: 0 | AW286: 0 | AX286: 0 | AY286: 1081339
A287: Orissa | C287: 285 | D287: 10 | E287: Jajpur | F287: 2014 | H287: 541349 | I287: 221078 | J287: 150789 | K287: 29142 | L287: 8655 | M287: 8269 | N287: 8065 | O287: 6926 | P287: 3409 | Q287: 2753 | R287: 0 | S287: 0 | T287: 0 | U287: 0 | V287: 0 | W287: 0 | X287: 0 | Y287: 0 | Z287: 0 | AA287: 0 | AB287: 0 | AC287: 0 | AD287: 0 | AE287: 0 | AF287: 0 | AG287: 0 | AH287: 0 | AI287: 0 | AJ287: 0 | AK287: 0 | AL287: 0 | AM287: 0 | AN287: 0 | AO287: 0 | AP287: 0 | AQ287: 0 | AR287: 0 | AS287: 0 | AT287: 0 | AU287: 0 | AV287: 0 | AW287: 0 | AX287: 0 | AY287: 980435
A288: Orissa | C288: 286 | D288: 13 | E288: Dhenkanal | F288: 2014 | H288: 453277 | I288: 315937 | J288: 213794 | K288: 13205 | L288: 8712 | M288: 7505 | N288: 6574 | O288: 5447 | P288: 5120 | Q288: 4275 | R288: 3918 | S288: 2298 | T288: 2039 | U288: 0 | V288: 0 | W288: 0 | X288: 0 | Y288: 0 | Z288: 0 | AA288: 0 | AB288: 0 | AC288: 0 | AD288: 0 | AE288: 0 | AF288: 0 | AG288: 0 | AH288: 0 | AI288: 0 | AJ288: 0 | AK288: 0 | AL288: 0 | AM288: 0 | AN288: 0 | AO288: 0 | AP288: 0 | AQ288: 0 | AR288: 0 | AS288: 0 | AT288: 0 | AU288: 0 | AV288: 0 | AW288: 0 | AX288: 0 | AY288: 1042101
...

Sheet LS-2014-values
G1: 0 | H1: 1 | I1: 2 | J1: 3 | K1: 4 | L1: 5 | M1: 6 | N1: 7 | O1: 8 | P1: 9 | Q1: 10 | R1: 11 | S1: 12 | T1: 13 | U1: 14 | V1: 15 | W1: 16 | X1: 17 | Y1: 18 | Z1: 19 | AA1: 20 | AB1: 21 | AC1: 22 | AD1: 23 | AE1: 24 | AF1: 25 | AG1: 26 | AH1: 27 | AI1: 28 | AJ1: 29 | AK1: 30 | AL1: 31 | AM1: 32 | AN1: 33 | AO1: 34 | AP1: 35 | AQ1: 36 | AR1: 37 | AS1: 38 | AT1: 39 | AU1: 40 | AV1: 41 | AW1: 42
A2: state | B2: statecode | C2: constituency_no | D2: No_Candidates | E2: constituency | F2: year | G2: first | H2: second | I2: third | J2: fourth | K2: fifth | L2: sixth | M2: seventh | N2: eighth | O2: ninth | P2: tenth | Q2: eleventh | R2: twelveth | S2: thirteenth | T2: fourteenth | U2: fifteenth | V2: sixteenth | W2: seventeenth | X2: eighteenth | Y2: nineteenth | Z2: twentieth | AA2: twentyfirst | AB2: twentysecond | AC2: twentythird | AD2: twentyfourth | AE2: twentyfifth | AF2: twentysixth | AG2: twentyseventh | AH2: twentyeighth | AI2: twentyninth | AJ2: thirtieth | AK2: thirtyfirst | AL2: thirtysecond | AM2: thirtythird | AN2: thirtyfourth | AO2: thirtyfifth | AP2: thirtysixth | AQ2: thirtyseventh | AR2: thirtyeightth | AS2: thirtyninth | AT2: fortieth | AU2: fortyfirst | AV2: fortysecond | AW2: fortythird | AX2: total
A3: Andhra Pradesh | C3: 1 | D3: 9 | E3: Adilabad | F3: 2014 | G3: 430847 | H3: 259557 | I3: 184198 | J3: 94420 | K3: 41032 | L3: 17084 | M3: 8859 | N3: 5055 | O3: 4787 | P3: 0 | Q3: 0 | R3: 0 | S3: 0 | T3: 0 | U3: 0 | V3: 0 | W3: 0 | X3: 0 | Y3: 0 | Z3: 0 | AA3: 0 | AB3: 0 | AC3: 0 | AD3: 0 | AE3: 0 | AF3: 0 | AG3: 0 | AH3: 0 | AI3: 0 | AJ3: 0 | AK3: 0 | AL3: 0 | AM3: 0 | AN3: 0 | AO3: 0 | AP3: 0 | AQ3: 0 | AR3: 0 | AS3: 0 | AT3: 0 | AU3: 0 | AV3: 0 | AW3: 0 | AX3: 1045839
A4: Andhra Pradesh | C4: 2 | D4: 18 | E4: Peddapalle | F4: 2014 | G4: 565496 | H4: 274338 | I4: 63334 | J4: 45977 | K4: 9449 | L4: 9290 | M4: 9199 | N4: 8609 | O4: 7258 | P4: 5361 | Q4: 3866 | R4: 3699 | S4: 3266 | T4: 3020 | U4: 2742 | V4: 2674 | W4: 2361 | X4: 2245 | Y4: 0 | Z4: 0 | AA4: 0 | AB4: 0 | AC4: 0 | AD4: 0 | AE4: 0 | AF4: 0 | AG4: 0 | AH4: 0 | AI4: 0 | AJ4: 0 | AK4: 0 | AL4: 0 | AM4: 0 | AN4: 0 | AO4: 0 | AP4: 0 | AQ4: 0 | AR4: 0 | AS4: 0 | AT4: 0 | AU4: 0 | AV4: 0 | AW4: 0 | AX4: 1022184
A5: Andhra Pradesh | C5: 3 | D5: 18 | E5: Karimnagar | F5: 2014 | G5: 505358 | H5: 300706 | I5: 214828 | J5: 39308 | K5: 11328 | L5: 8034 | M5: 6713 | N5: 5734 | O5: 4769 | P5: 4728 | Q5: 3943 | R5: 3851 | S5: 3772 | T5: 3075 | U5: 2757 | V5: 2445 | W5: 2062 | X5: 1773 | Y5: 0 | Z5: 0 | AA5: 0 | AB5: 0 | AC5: 0 | AD5: 0 | AE5: 0 | AF5: 0 | AG5: 0 | AH5: 0 | AI5: 0 | AJ5: 0 | AK5: 0 | AL5: 0 | AM5: 0 | AN5: 0 | AO5: 0 | AP5: 0 | AQ5: 0 | AR5: 0 | AS5: 0 | AT5: 0 | AU5: 0 | AV5: 0 | AW5: 0 | AX5: 1125184
A6: Andhra Pradesh | C6: 4 | D6: 17 | E6: Nizamabad | F6: 2014 | G6: 439307 | H6: 272123 | I6: 225333 | J6: 43814 | K6: 8129 | L6: 7421 | M6: 7266 | N6: 4791 | O6: 3990 | P6: 3651 | Q6: 3529 | R6: 3091 | S6: 2817 | T6: 2621 | U6: 2462 | V6: 1978 | W6: 1601 | X6: 0 | Y6: 0 | Z6: 0 | AA6: 0 | AB6: 0 | AC6: 0 | AD6: 0 | AE6: 0 | AF6: 0 | AG6: 0 | AH6: 0 | AI6: 0 | AJ6: 0 | AK6: 0 | AL6: 0 | AM6: 0 | AN6: 0 | AO6: 0 | AP6: 0 | AQ6: 0 | AR6: 0 | AS6: 0 | AT6: 0 | AU6: 0 | AV6: 0 | AW6: 0 | AX6: 1033924
A7: Andhra Pradesh | C7: 5 | D7: 11 | E7: Zahirabad | F7: 2014 | G7: 508661 | H7: 364030 | I7: 157497 | J7: 18027 | K7: 12383 | L7: 11190 | M7: 8180 | N7: 4804 | O7: 4426 | P7: 3285 | Q7: 2323 | R7: 0 | S7: 0 | T7: 0 | U7: 0 | V7: 0 | W7: 0 | X7: 0 | Y7: 0 | Z7: 0 | AA7: 0 | AB7: 0 | AC7: 0 | AD7: 0 | AE7: 0 | AF7: 0 | AG7: 0 | AH7: 0 | AI7: 0 | AJ7: 0 | AK7: 0 | AL7: 0 | AM7: 0 | AN7: 0 | AO7: 0 | AP7: 0 | AQ7: 0 | AR7: 0 | AS7: 0 | AT7: 0 | AU7: 0 | AV7: 0 | AW7: 0 | AX7: 1094806
A8: Andhra Pradesh | C8: 6 | D8: 14 | E8: Medak | F8: 2014 | G8: 657492 | H8: 260463 | I8: 181804 | J8: 33507 | K8: 11752 | L8: 10696 | M8: 7599 | N8: 6643 | O8: 5010 | P8: 4441 | Q8: 3297 | R8: 3281 | S8: 2973 | T8: 2053 | U8: 0 | V8: 0 | W8: 0 | X8: 0 | Y8: 0 | Z8: 0 | AA8: 0 | AB8: 0 | AC8: 0 | AD8: 0 | AE8: 0 | AF8: 0 | AG8: 0 | AH8: 0 | AI8: 0 | AJ8: 0 | AK8: 0 | AL8: 0 | AM8: 0 | AN8: 0 | AO8: 0 | AP8: 0 | AQ8: 0 | AR8: 0 | AS8: 0 | AT8: 0 | AU8: 0 | AV8: 0 | AW8: 0 | AX8: 1191011
A9: Andhra Pradesh | C9: 7 | D9: 31 | E9: Malkajgiri | F9: 2014 | G9: 523356 | H9: 495190 | I9: 233530 | J9: 158248 | K9: 115221 | L9: 18544 | M9: 13239 | N9: 8692 | O9: 8301 | P9: 7953 | Q9: 6133 | R9: 5717 | S9: 4095 | T9: 2677 | U9: 2261 | V9: 2049 | W9: 1693 | X9: 1547 | Y9: 1416 | Z9: 1390 | AA9: 1325 | AB9: 1301 | AC9: 1032 | AD9: 1026 | AE9: 899 | AF9: 802 | AG9: 775 | AH9: 596 | AI9: 529 | AJ9: 496 | AK9: 411 | AL9: 0 | AM9: 0 | AN9: 0 | AO9: 0 | AP9: 0 | AQ9: 0 | AR9: 0 | AS9: 0 | AT9: 0 | AU9: 0 | AV9: 0 | AW9: 0 | AX9: 1620444
A10: Andhra Pradesh | C10: 8 | D10: 31 | E10: Secundrabad | F10: 2014 | G10: 438271 | H10: 183536 | I10: 145120 | J10: 143847 | K10: 45187 | L10: 11184 | M10: 6572 | N10: 3691 | O10: 2863 | P10: 2603 | Q10: 2481 | R10: 2311 | S10: 2058 | T10: 1813 | U10: 1496 | V10: 1144 | W10: 959 | X10: 928 | Y10: 886 | Z10: 873 | AA10: 809 | AB10: 786 | AC10: 779 | AD10: 638 | AE10: 554 | AF10: 547 | AG10: 474 | AH10: 376 | AI10: 370 | AJ10: 322 | AK10: 291 | AL10: 0 | AM10: 0 | AN10: 0 | AO10: 0 | AP10: 0 | AQ10: 0 | AR10: 0 | AS10: 0 | AT10: 0 | AU10: 0 | AV10: 0 | AW10: 0 | AX10: 1003769
A11: Andhra Pradesh | C11: 9 | D11: 17 | E11: Hyderbad | F11: 2014 | G11: 513868 | H11: 311414 | I11: 49310 | J11: 37195 | K11: 21796 | L11: 10743 | M11: 6118 | N11: 5992 | O11: 5013 | P11: 3100 | Q11: 2102 | R11: 1593 | S11: 740 | T11: 728 | U11: 626 | V11: 598 | W11: 485 | X11: 0 | Y11: 0 | Z11: 0 | AA11: 0 | AB11: 0 | AC11: 0 | AD11: 0 | AE11: 0 | AF11: 0 | AG11: 0 | AH11: 0 | AI11: 0 | AJ11: 0 | AK11: 0 | AL11: 0 | AM11: 0 | AN11: 0 | AO11: 0 | AP11: 0 | AQ11: 0 | AR11: 0 | AS11: 0 | AT11: 0 | AU11: 0 | AV11: 0 | AW11: 0 | AX11: 971421
A12: Andhra Pradesh | C12: 10 | D12: 16 | E12: Chelvella | F12: 2014 | G12: 435077 | H12: 362054 | I12: 353203 | J12: 56835 | K12: 40135 | L12: 24660 | M12: 10018 | N12: 7732 | O12: 7462 | P12: 5789 | Q12: 2904 | R12: 2545 | S12: 2214 | T12: 2058 | U12: 1765 | V12: 1411 | W12: 0 | X12: 0 | Y12: 0 | Z12: 0 | AA12: 0 | AB12: 0 | AC12: 0 | AD12: 0 | AE12: 0 | AF12: 0 | AG12: 0 | AH12: 0 | AI12: 0 | AJ12: 0 | AK12: 0 | AL12: 0 | AM12: 0 | AN12: 0 | AO12: 0 | AP12: 0 | AQ12: 0 | AR12: 0 | AS12: 0 | AT12: 0 | AU12: 0 | AV12: 0 | AW12: 0 | AX12: 1315862
A13: Andhra Pradesh | C13: 11 | D13: 10 | E13: Mahbubnagar | F13: 2014 | G13: 334228 | H13: 331638 | I13: 272791 | J13: 30388 | K13: 15779 | L13: 9105 | M13: 9037 | N13: 4549 | O13: 4033 | P13: 3252 | Q13: 0 | R13: 0 | S13: 0 | T13: 0 | U13: 0 | V13: 0 | W13: 0 | X13: 0 | Y13: 0 | Z13: 0 | AA13: 0 | AB13: 0 | AC13: 0 | AD13: 0 | AE13: 0 | AF13: 0 | AG13: 0 | AH13: 0 | AI13: 0 | AJ13: 0 | AK13: 0 | AL13: 0 | AM13: 0 | AN13: 0 | AO13: 0 | AP13: 0 | AQ13: 0 | AR13: 0 | AS13: 0 | AT13: 0 | AU13: 0 | AV13: 0 | AW13: 0 | AX13: 1014800
A14: Andhra Pradesh | C14: 12 | D14: 7 | E14: Nagarkurnool | F14: 2014 | G14: 420075 | H14: 403399 | I14: 183352 | J14: 54680 | K14: 22985 | L14: 12388 | M14: 12089 | N14: 0 | O14: 0 | P14: 0 | Q14: 0 | R14: 0 | S14: 0 | T14: 0 | U14: 0 | V14: 0 | W14: 0 | X14: 0 | Y14: 0 | Z14: 0 | AA14: 0 | AB14: 0 | AC14: 0 | AD14: 0 | AE14: 0 | AF14: 0 | AG14: 0 | AH14: 0 | AI14: 0 | AJ14: 0 | AK14: 0 | AL14: 0 | AM14: 0 | AN14: 0 | AO14: 0 | AP14: 0 | AQ14: 0 | AR14: 0 | AS14: 0 | AT14: 0 | AU14: 0 | AV14: 0 | AW14: 0 | AX14: 1108968
... A545: Puducherry | C545: 543 | D545: 31 | E545: Puducherry | F545: 2014 | G545: 255826 | H545: 194972 | I545: 132657 | J545: 60580 | K545: 22754 | L545: 22268 | M545: 12709 | N545: 8307 | O545: 5896 | P545: 3472 | Q545: 2494 | R545: 2060 | S545: 1777 | T545: 1726 | U545: 1442 | V545: 1340 | W545: 1270 | X545: 1236 | Y545: 1144 | Z545: 767 | AA545: 747 | AB545: 746 | AC545: 610 | AD545: 497 | AE545: 477 | AF545: 467 | AG545: 465 | AH545: 438 | AI545: 366 | AJ545: 309 | AK545: 198 | AL545: 0 | AM545: 0 | AN545: 0 | AO545: 0 | AP545: 0 | AQ545: 0 | AR545: 0 | AS545: 0 | AT545: 0 | AU545: 0 | AV545: 0 | AW545: 0 | AX545: 740017
